<mujoco model="elf3">
  <compiler angle="radian" meshdir="./meshes/" autolimits="true"/>

  <size nkey="1"/>

  <default>
    <default class="elf3">
      <geom type="mesh" contype="0" conaffinity="0" group="2" density="0" material="silver"/>
      <site group="5" rgba="1 0 0 1"/>
      <default class="collision">
        <geom type="capsule" contype="1" conaffinity="1" group="3" rgba="0.2 0.6 0.2 0.3"/>
        <default class="foot_capsule">
          <geom size="0.01 0 0"/>
        </default>
      </default>
    </default>
  </default>

  <asset>
    <material name="silver" rgba="0.7 0.7 0.7 1"/>
    <material name="black" rgba="0.2 0.2 0.2 1"/>
    <mesh name="torso_link" file="torso_link.STL"/>
    <mesh name="waist_y_link" file="waist_y_link.STL"/>
    <mesh name="waist_x_link" file="waist_x_link.STL"/>
    <mesh name="waist_z_link" file="waist_z_link.STL"/>
    <mesh name="l_hip_y_link" file="l_hip_y_link.STL"/>
    <mesh name="l_hip_x_link" file="l_hip_x_link.STL"/>
    <mesh name="l_hip_z_link" file="l_hip_z_link.STL"/>
    <mesh name="l_knee_y_link" file="l_knee_y_link.STL"/>
    <mesh name="l_ankle_y_link" file="l_ankle_y_link.STL"/>
    <mesh name="l_ankle_x_link" file="l_ankle_x_link.STL"/>
    <mesh name="r_hip_y_link" file="r_hip_y_link.STL"/>
    <mesh name="r_hip_x_link" file="r_hip_x_link.STL"/>
    <mesh name="r_hip_z_link" file="r_hip_z_link.STL"/>
    <mesh name="r_knee_y_link" file="r_knee_y_link.STL"/>
    <mesh name="r_ankle_y_link" file="r_ankle_y_link.STL"/>
    <mesh name="r_ankle_x_link" file="r_ankle_x_link.STL"/>
    <mesh name="l_shoulder_y_link" file="l_shoulder_y_link.STL"/>
    <mesh name="l_shoulder_x_link" file="l_shoulder_x_link.STL"/>
    <mesh name="l_shoulder_z_link" file="l_shoulder_z_link.STL"/>
    <mesh name="l_elbow_y_link" file="l_elbow_y_link.STL"/>
    <mesh name="l_wrist_x_link" file="l_wrist_x_link.STL"/>
    <mesh name="l_wrist_y_link" file="l_wrist_y_link.STL"/>
    <mesh name="l_wrist_z_link" file="l_wrist_z_link.STL"/>
    <mesh name="r_shoulder_y_link" file="r_shoulder_y_link.STL"/>
    <mesh name="r_shoulder_x_link" file="r_shoulder_x_link.STL"/>
    <mesh name="r_shoulder_z_link" file="r_shoulder_z_link.STL"/>
    <mesh name="r_elbow_y_link" file="r_elbow_y_link.STL"/>
    <mesh name="r_wrist_x_link" file="r_wrist_x_link.STL"/>
    <mesh name="r_wrist_y_link" file="r_wrist_y_link.STL"/>
    <mesh name="r_wrist_z_link" file="r_wrist_z_link.STL"/>
  </asset>

  <worldbody>
    <body name="torso_link" childclass="elf3" pos="0 0 1.1">
      <inertial pos="0.001601 0.000219 0.02325" quat="0.999996 -0.00137768 -0.000418876 -0.00258007" mass="12.004" diaginertia="0.293168 0.265897 0.0611617"/>
      <joint name="world_joint" type="free"/>
      <geom rgba="0.75294 0.75294 0.75294 1" mesh="torso_link"/>
      <geom name="torso_collision" class="collision" size="0.09 0.1" pos="0 0 -0.02" quat="0 1 0 0" condim="1"/>
      <geom name="torso_2_collision" class="collision" size="0.08 0.025" pos="0 0 -0.12" quat="0.707107 0.707107 0 0" condim="1"/>
      <site name="imu_in_torso" pos="0 0 0" size="0.01"/>
      <camera name="tracking" pos="1.734 -1.135 0.35" quat="0.683353 0.555871 0.298684 0.367183" mode="trackcom"/>
      <light pos="0 0 2" dir="0 0 -1" mode="trackcom"/>
      <body name="waist_y_link" pos="0 0 -0.2265">
        <inertial pos="0 0 0" quat="0 0.707107 0 0.707107" mass="0.0661518" diaginertia="2.799e-05 1.845e-05 1.104e-05"/>
        <joint name="waist_y_joint" pos="0 0 0" axis="0 1 0" range="-0.5236 0.5236" armature="0.0274702"/>
        <geom rgba="0.752941 0.752941 0.752941 1" mesh="waist_y_link"/>
        <body name="waist_x_link">
          <inertial pos="-0.0105041 6.39183e-08 -0.0167973" quat="0 0.79615 0 0.605099" mass="0.215643" diaginertia="0.000266195 0.00017942 0.000134265"/>
          <joint name="waist_x_joint" pos="0 0 0" axis="1 0 0" range="-0.2618 0.2618" armature="0.0412054"/>
          <geom rgba="0.752941 0.752941 0.752941 1" mesh="waist_x_link"/>
          <body name="waist_z_link">
            <inertial pos="-1.01283e-06 1.1248e-05 -0.126152" quat="1 6.14768e-11 -6.32993e-05 -9.71208e-07" mass="4.95603" diaginertia="0.0210971 0.0159488 0.013672"/>
            <joint name="waist_z_joint" pos="0 0 0" axis="0 0 1" range="-2.8798 2.8798" armature="0.044688"/>
            <geom rgba="0.752941 0.752941 0.752941 1" mesh="waist_z_link"/>
            <geom name="waist_z_1_collision" class="collision" size="0.055 0.03" pos="0 0 -0.156" quat="0.707107 0.707107 0 0" condim="1"/>
            <geom name="waist_z_2_collision" class="collision" size="0.055 0.053" pos="0 0 -0.103" quat="0 1 0 0" condim="1"/>
            <body name="elf3_pelvis_link" pos="0 0 -0.156">
              <inertial pos="0 0 0" mass="0.001" diaginertia="1e-7 1e-7 1e-7"/>
              <geom type="sphere" size="0.005" rgba="0.2 0.2 0.2 1" contype="0" conaffinity="0" density="0" group="1"/>
            </body>
            <body name="l_hip_y_link" pos="0 0.136 -0.156">
              <inertial pos="-0.021777 -0.00277946 0.000699282" quat="0.796416 0.601232 0.0517671 0.039512" mass="1.70385" diaginertia="0.00281533 0.00218511 0.0019944"/>
              <joint name="l_hip_y_joint" pos="0 0 0" axis="0 1 0" range="-2.8798 2.8798" armature="0.044688"/>
              <geom rgba="0.752941 0.752941 0.752941 1" mesh="l_hip_y_link"/>
              <body name="l_hip_x_link">
                <inertial pos="0.0163074 1.05982e-08 -0.0384681" quat="0.997755 0 0.066975 0" mass="0.214152" diaginertia="0.000346601 0.00030038 0.000125989"/>
                <joint name="l_hip_x_joint" pos="0 0 0" axis="1 0 0" range="-0.48869 3.0543" armature="0.044688"/>
                <geom rgba="0.752941 0.752941 0.752941 1" mesh="l_hip_x_link"/>
                <geom name="l_hip_x_collision" class="collision" size="0.05 0.0175" pos="-0.0175 0 0" quat="0.707107 0 -0.707107 0" condim="1"/>
                <body name="l_hip_z_link">
                  <inertial pos="0.00128858 -0.00894579 -0.233969" quat="0.684622 -0.027855 0.0299671 0.727749" mass="2.84278" diaginertia="0.0321197 0.031121 0.0032734"/>
                  <joint name="l_hip_z_joint" pos="0 0 0" axis="0 0 1" range="-2.8798 2.8798" armature="0.0137351"/>
                  <geom rgba="0.752941 0.752941 0.752941 1" mesh="l_hip_z_link"/>
                  <geom name="l_hip_z_1_collision" class="collision" size="0.05 0.1" pos="0 0 -0.22" condim="1"/>
                  <geom name="l_hip_z_2_collision" class="collision" size="0.05 0.0125" pos="0 -0.0125 -0.32" quat="0.707107 0.707107 0 0" condim="1"/>
                  <body name="l_knee_y_link" pos="0 0 -0.32">
                    <inertial pos="0.00743378 0.00339915 -0.143783" quat="0.824887 -0.0250601 0.0341455 0.563709" mass="1.77391" diaginertia="0.00878814 0.00856731 0.00138834"/>
                    <joint name="l_knee_y_joint" pos="0 0 0" axis="0 1 0" range="-0.087266 2.618" armature="0.044688"/>
                    <geom rgba="0.752941 0.752941 0.752941 1" mesh="l_knee_y_link"/>
                    <geom name="l_knee_y_collision" class="collision" size="0.05 0.07" pos="0 0 -0.19" condim="1"/>
                    <body name="l_ankle_y_link" pos="0 0 -0.32">
                      <inertial pos="0 0 -4.1832e-09" quat="0.5 0.5 -0.5 0.5" mass="0.0126899" diaginertia="1.55e-06 1.31e-06 5.9e-07"/>
                      <joint name="l_ankle_y_joint" pos="0 0 0" axis="0 1 0" range="-0.87266 0.7854" armature="0.00848397"/>
                      <geom rgba="0.752941 0.752941 0.752941 1" mesh="l_ankle_y_link"/>
                      <body name="l_ankle_x_link">
                        <inertial pos="0.0275442 6.46069e-10 -0.0292972" quat="0 0.713286 0 0.700873" mass="0.298065" diaginertia="0.00150765 0.00138193 0.000163046"/>
                        <joint name="l_ankle_x_joint" pos="0 0 0" axis="1 0 0" range="-0.34907 0.34907" armature="0.00551458"/>
                        <geom rgba="0.752941 0.752941 0.752941 1" mesh="l_ankle_x_link"/>
                        <geom name="l_foot1_collision" class="foot_capsule" size="0.01 0.09" pos="0.03 -0.03 -0.03" quat="0.707107 0 -0.707107 0" priority="1" friction="0.6"/>
                        <geom name="l_foot2_collision" class="foot_capsule" size="0.01 0.1" pos="0.03 -0.02 -0.03" quat="0.707107 0 -0.707107 0" priority="1" friction="0.6"/>
                        <geom name="l_foot3_collision" class="foot_capsule" size="0.01 0.105" pos="0.03 -0.01 -0.03" quat="0.707107 0 -0.707107 0" priority="1" friction="0.6"/>
                        <geom name="l_foot4_collision" class="foot_capsule" size="0.01 0.11" pos="0.03 0 -0.03" quat="0.707107 0 -0.707107 0" priority="1" friction="0.6"/>
                        <geom name="l_foot5_collision" class="foot_capsule" size="0.01 0.105" pos="0.03 0.01 -0.03" quat="0.707107 0 -0.707107 0" priority="1" friction="0.6"/>
                        <geom name="l_foot6_collision" class="foot_capsule" size="0.01 0.1" pos="0.03 0.02 -0.03" quat="0.707107 0 -0.707107 0" priority="1" friction="0.6"/>
                        <geom name="l_foot7_collision" class="foot_capsule" size="0.01 0.09" pos="0.03 0.03 -0.03" quat="0.707107 0 -0.707107 0" priority="1" friction="0.6"/>
                        <site name="l_foot" pos="0 0 0"/>
                        <body name="left_foot_toe_link" pos="0.14 0 -0.03">
                          <inertial pos="0 0 0" mass="0.001" diaginertia="1e-7 1e-7 1e-7"/>
                          <geom type="sphere" size="0.005" rgba="0.2 0.2 0.2 1" contype="0" conaffinity="0" density="0" group="1"/>
                        </body>
                        <body name="left_foot_toe_outer_link" pos="0.12 0.03 -0.03">
                          <inertial pos="0 0 0" mass="0.001" diaginertia="1e-7 1e-7 1e-7"/>
                          <geom type="sphere" size="0.005" rgba="0.2 0.2 0.2 1" contype="0" conaffinity="0" density="0" group="1"/>
                        </body>
                        <body name="left_foot_toe_inner_link" pos="0.12 -0.03 -0.03">
                          <inertial pos="0 0 0" mass="0.001" diaginertia="1e-7 1e-7 1e-7"/>
                          <geom type="sphere" size="0.005" rgba="0.2 0.2 0.2 1" contype="0" conaffinity="0" density="0" group="1"/>
                        </body>
                        <body name="left_foot_heel_outer_link" pos="-0.05 0.025 -0.03">
                          <inertial pos="0 0 0" mass="0.001" diaginertia="1e-7 1e-7 1e-7"/>
                          <geom type="sphere" size="0.005" rgba="0.2 0.2 0.2 1" contype="0" conaffinity="0" density="0" group="1"/>
                        </body>
                        <body name="left_foot_heel_inner_link" pos="-0.05 -0.025 -0.03">
                          <inertial pos="0 0 0" mass="0.001" diaginertia="1e-7 1e-7 1e-7"/>
                          <geom type="sphere" size="0.005" rgba="0.2 0.2 0.2 1" contype="0" conaffinity="0" density="0" group="1"/>
                        </body>
                      </body>
                    </body>
                  </body>
                </body>
              </body>
            </body>
            <body name="r_hip_y_link" pos="0 -0.136 -0.156">
              <inertial pos="-0.021777 0.00272279 0.000731999" quat="0.602526 0.795307 -0.042061 -0.0517694" mass="1.70385" diaginertia="0.00281648 0.0021855 0.00199374"/>
              <joint name="r_hip_y_joint" pos="0 0 0" axis="0 1 0" range="-2.8798 2.8798" armature="0.044688"/>
              <geom rgba="0.752941 0.752941 0.752941 1" mesh="r_hip_y_link"/>
              <body name="r_hip_x_link">
                <inertial pos="0.0163074 1.05982e-08 -0.0384681" quat="0.997755 0 0.066975 0" mass="0.214152" diaginertia="0.000346601 0.00030038 0.000125989"/>
                <joint name="r_hip_x_joint" pos="0 0 0" axis="1 0 0" range="-3.0543 0.48869" armature="0.044688"/>
                <geom rgba="0.752941 0.752941 0.752941 1" mesh="r_hip_x_link"/>
                <geom name="r_hip_x_collision" class="collision" size="0.05 0.0175" pos="-0.0175 0 0" quat="0.707107 0 -0.707107 0" condim="1"/>
                <body name="r_hip_z_link">
                  <inertial pos="0.00128913 0.00895213 -0.233968" quat="0.727741 0.0299428 -0.0278367 0.684632" mass="2.84278" diaginertia="0.0321189 0.0311203 0.00327334"/>
                  <joint name="r_hip_z_joint" pos="0 0 0" axis="0 0 1" range="-2.8798 2.8798" armature="0.0137351"/>
                  <geom rgba="0.752941 0.752941 0.752941 1" mesh="r_hip_z_link"/>
                  <geom name="r_hip_z_1_collision" class="collision" size="0.05 0.1" pos="0 0 -0.22" condim="1"/>
                  <geom name="r_hip_z_2_collision" class="collision" size="0.05 0.0125" pos="0 0.0125 -0.32" quat="0.707107 -0.707107 0 0" condim="1"/>
                  <body name="r_knee_y_link" pos="0 0 -0.32">
                    <inertial pos="0.00743378 -0.00337367 -0.143783" quat="0.561231 0.034056 -0.025158 0.826576" mass="1.77391" diaginertia="0.00878933 0.00856646 0.00138868"/>
                    <joint name="r_knee_y_joint" pos="0 0 0" axis="0 1 0" range="-0.087266 2.618" armature="0.044688"/>
                    <geom rgba="0.752941 0.752941 0.752941 1" mesh="r_knee_y_link"/>
                    <geom name="r_knee_y_collision" class="collision" size="0.05 0.07" pos="0 0 -0.19" condim="1"/>
                    <body name="r_ankle_y_link" pos="0 0 -0.32">
                      <inertial pos="0 0 -4.18322e-09" quat="0.5 0.5 -0.5 0.5" mass="0.0126899" diaginertia="1.55e-06 1.31e-06 5.9e-07"/>
                      <joint name="r_ankle_y_joint" pos="0 0 0" axis="0 1 0" range="-0.87266 0.7854" armature="0.00848397"/>
                      <geom rgba="0.752941 0.752941 0.752941 1" mesh="r_ankle_y_link"/>
                      <body name="r_ankle_x_link">
                        <inertial pos="0.0275442 6.46053e-10 -0.0292972" quat="0 0.713286 0 0.700873" mass="0.298065" diaginertia="0.00150765 0.00138193 0.000163046"/>
                        <joint name="r_ankle_x_joint" pos="0 0 0" axis="1 0 0" range="-0.34907 0.34907" armature="0.00551458"/>
                        <geom rgba="0.752941 0.752941 0.752941 1" mesh="r_ankle_x_link"/>
                        <geom name="r_foot1_collision" class="foot_capsule" size="0.01 0.09" pos="0.03 -0.03 -0.03" quat="0.707107 0 -0.707107 0" priority="1" friction="0.6"/>
                        <geom name="r_foot2_collision" class="foot_capsule" size="0.01 0.1" pos="0.03 -0.02 -0.03" quat="0.707107 0 -0.707107 0" priority="1" friction="0.6"/>
                        <geom name="r_foot3_collision" class="foot_capsule" size="0.01 0.105" pos="0.03 -0.01 -0.03" quat="0.707107 0 -0.707107 0" priority="1" friction="0.6"/>
                        <geom name="r_foot4_collision" class="foot_capsule" size="0.01 0.11" pos="0.03 0 -0.03" quat="0.707107 0 -0.707107 0" priority="1" friction="0.6"/>
                        <geom name="r_foot5_collision" class="foot_capsule" size="0.01 0.105" pos="0.03 0.01 -0.03" quat="0.707107 0 -0.707107 0" priority="1" friction="0.6"/>
                        <geom name="r_foot6_collision" class="foot_capsule" size="0.01 0.1" pos="0.03 0.02 -0.03" quat="0.707107 0 -0.707107 0" priority="1" friction="0.6"/>
                        <geom name="r_foot7_collision" class="foot_capsule" size="0.01 0.09" pos="0.03 0.03 -0.03" quat="0.707107 0 -0.707107 0" priority="1" friction="0.6"/>
                        <site name="r_foot" pos="0 0 0"/>
                        <body name="right_foot_toe_link" pos="0.14 0 -0.03">
                          <inertial pos="0 0 0" mass="0.001" diaginertia="1e-7 1e-7 1e-7"/>
                          <geom type="sphere" size="0.005" rgba="0.2 0.2 0.2 1" contype="0" conaffinity="0" density="0" group="1"/>
                        </body>
                        <body name="right_foot_toe_outer_link" pos="0.12 0.03 -0.03">
                          <inertial pos="0 0 0" mass="0.001" diaginertia="1e-7 1e-7 1e-7"/>
                          <geom type="sphere" size="0.005" rgba="0.2 0.2 0.2 1" contype="0" conaffinity="0" density="0" group="1"/>
                        </body>
                        <body name="right_foot_toe_inner_link" pos="0.12 -0.03 -0.03">
                          <inertial pos="0 0 0" mass="0.001" diaginertia="1e-7 1e-7 1e-7"/>
                          <geom type="sphere" size="0.005" rgba="0.2 0.2 0.2 1" contype="0" conaffinity="0" density="0" group="1"/>
                        </body>
                        <body name="right_foot_heel_outer_link" pos="-0.05 0.025 -0.03">
                          <inertial pos="0 0 0" mass="0.001" diaginertia="1e-7 1e-7 1e-7"/>
                          <geom type="sphere" size="0.005" rgba="0.2 0.2 0.2 1" contype="0" conaffinity="0" density="0" group="1"/>
                        </body>
                        <body name="right_foot_heel_inner_link" pos="-0.05 -0.025 -0.03">
                          <inertial pos="0 0 0" mass="0.001" diaginertia="1e-7 1e-7 1e-7"/>
                          <geom type="sphere" size="0.005" rgba="0.2 0.2 0.2 1" contype="0" conaffinity="0" density="0" group="1"/>
                        </body>
                      </body>
                    </body>
                  </body>
                </body>
              </body>
            </body>
          </body>
        </body>
      </body>
      <body name="l_shoulder_y_link" pos="0 0.178 0.087">
        <inertial pos="-0.0194828 -0.00304252 0.000461368" quat="0.751186 0.652944 0.0750571 0.0612398" mass="0.938483" diaginertia="0.00102195 0.000817739 0.000721669"/>
        <joint name="l_shoulder_y_joint" pos="0 0 0" axis="0 1 0" range="-2.8798 2.8798" armature="0.0137351"/>
        <geom rgba="0.752941 0.752941 0.752941 1" mesh="l_shoulder_y_link"/>
        <body name="l_shoulder_x_link">
          <inertial pos="0.00939873 1.86326e-09 -0.0272171" quat="0.994844 0 0.101416 0" mass="0.130651" diaginertia="0.000139965 0.00011597 5.88054e-05"/>
          <joint name="l_shoulder_x_joint" pos="0 0 0" axis="1 0 0" range="-0.34907 3.0543" armature="0.0137351"/>
          <geom rgba="0.752941 0.752941 0.752941 1" mesh="l_shoulder_x_link"/>
          <geom name="l_shoulder_x_collision" class="collision" size="0.04 0.015" pos="-0.015 0 0" quat="0.707107 0 -0.707107 0" condim="1"/>
          <body name="l_shoulder_z_link">
            <inertial pos="-0.000948901 -0.00269014 -0.207899" quat="0.734549 -0.0171253 0.014469 0.678185" mass="1.29694" diaginertia="0.00804984 0.00776246 0.000985623"/>
            <joint name="l_shoulder_z_joint" pos="0 0 0" axis="0 0 1" range="-2.8798 2.8798" armature="0.00424198"/>
            <geom rgba="0.752941 0.752941 0.752941 1" mesh="l_shoulder_z_link"/>
            <geom name="l_shoulder_z_1_collision" class="collision" size="0.035 0.095" pos="0 0 -0.175" condim="1"/>
            <geom name="l_shoulder_z_2_collision" class="collision" size="0.04 0.0125" pos="0 -0.0025 -0.256" quat="0.707107 0.707107 0 0" condim="1"/>
            <body name="l_elbow_y_link" pos="0 0 -0.256">
              <inertial pos="0.0294656 0.0164098 -3.3401e-10" quat="0.582167 0.582167 0.40135 0.40135" mass="0.0938669" diaginertia="9.24069e-05 8.443e-05 3.65431e-05"/>
              <joint name="l_elbow_y_joint" pos="0 0 0" axis="0 1 0" range="-0.95993 1.6581" armature="0.0137351"/>
              <geom rgba="0.752941 0.752941 0.752941 1" mesh="l_elbow_y_link"/>
              <geom name="l_elbow_y_collision" class="collision" size="0.04 0.06" pos="0.14 0 0" quat="0.707107 0 -0.707107 0" condim="1"/>
              <body name="l_wrist_x_link" pos="0.256 0 0">
                <inertial pos="-0.124483 -0.00110033 3.42813e-05" quat="0.0116702 0.706947 -0.0126884 0.707056" mass="0.658675" diaginertia="0.00208306 0.00183553 0.000544518"/>
                <joint name="l_wrist_x_joint" pos="0 0 0" axis="1 0 0" range="-2.8798 2.8798" armature="0.00424198"/>
                <geom rgba="0.752941 0.752941 0.752941 1" mesh="l_wrist_x_link"/>
                <body name="l_wrist_y_link">
                  <inertial pos="-1.24357e-05 -0.000129932 -0.00298556" quat="0.70598 -0.00177876 0.00246071 0.708225" mass="0.243805" diaginertia="0.000186762 0.00018369 0.000141738"/>
                  <joint name="l_wrist_y_joint" pos="0 0 0" axis="0 1 0" range="-1.309 1.309" armature="0.00424198"/>
                  <geom rgba="0.752941 0.752941 0.752941 1" mesh="l_wrist_y_link"/>
                  <body name="l_wrist_z_link">
                    <inertial pos="0.0308695 1.39176e-09 0.0141752" quat="0.924847 0 -0.380338 0" mass="0.106561" diaginertia="9.65613e-05 8.685e-05 4.53187e-05"/>
                    <joint name="l_wrist_z_joint" pos="0 0 0" axis="0 0 1" range="-0.7854 0.7854" armature="0.00424198"/>
                    <geom rgba="0.752941 0.752941 0.752941 1" mesh="l_wrist_z_link"/>
                    <geom name="l_wrist_z_collision" class="collision" size="0.03" pos="0.04 0 0" type="sphere" condim="1"/>
                  </body>
                </body>
              </body>
            </body>
          </body>
        </body>
      </body>
      <body name="r_shoulder_y_link" pos="0 -0.178 0.087">
        <inertial pos="-0.0194828 0.00304195 0.00046038" quat="0.652921 0.751201 -0.0612164 -0.0751263" mass="0.938483" diaginertia="0.00102196 0.000817748 0.00072166"/>
        <joint name="r_shoulder_y_joint" pos="0 0 0" axis="0 1 0" range="-2.8798 2.8798" armature="0.0137351"/>
        <geom rgba="0.752941 0.752941 0.752941 1" mesh="r_shoulder_y_link"/>
        <body name="r_shoulder_x_link">
          <inertial pos="0.00939873 1.86336e-09 -0.0272171" quat="0.994844 0 0.101416 0" mass="0.130651" diaginertia="0.000139965 0.00011597 5.88054e-05"/>
          <joint name="r_shoulder_x_joint" pos="0 0 0" axis="1 0 0" range="-3.0543 0.34907" armature="0.0137351"/>
          <geom rgba="0.752941 0.752941 0.752941 1" mesh="r_shoulder_x_link"/>
          <geom name="r_shoulder_x_collision" class="collision" size="0.04 0.015" pos="-0.015 0 0" quat="0.707107 0 -0.707107 0" condim="1"/>
          <body name="r_shoulder_z_link">
            <inertial pos="-0.000936876 0.00267273 -0.207892" quat="0.677531 0.014495 -0.0172678 0.735148" mass="1.29694" diaginertia="0.00804923 0.00776163 0.000985616"/>
            <joint name="r_shoulder_z_joint" pos="0 0 0" axis="0 0 1" range="-2.8798 2.8798" armature="0.00424198"/>
            <geom rgba="0.752941 0.752941 0.752941 1" mesh="r_shoulder_z_link"/>
            <geom name="r_shoulder_z_1_collision" class="collision" size="0.035 0.095" pos="0 0 -0.175" condim="1"/>
            <geom name="r_shoulder_z_2_collision" class="collision" size="0.04 0.0125" pos="0 0.0025 -0.256" quat="0.707107 -0.707107 0 0" condim="1"/>
            <body name="r_elbow_y_link" pos="0 0 -0.256">
              <inertial pos="0.0294656 -0.0164098 -6.94346e-10" quat="0.40135 0.40135 0.582167 0.582167" mass="0.0938669" diaginertia="9.24069e-05 8.443e-05 3.65431e-05"/>
              <joint name="r_elbow_y_joint" pos="0 0 0" axis="0 1 0" range="-0.95993 1.6581" armature="0.0137351"/>
              <geom rgba="0.752941 0.752941 0.752941 1" mesh="r_elbow_y_link"/>
              <geom name="r_elbow_y_collision" class="collision" size="0.04 0.06" pos="0.14 0 0" quat="0.707107 0 -0.707107 0" condim="1"/>
              <body name="r_wrist_x_link" pos="0.256 0 0">
                <inertial pos="-0.124486 0.00109279 3.42822e-05" quat="-0.0117266 0.706953 0.0127993 0.707048" mass="0.658675" diaginertia="0.0020829 0.00183538 0.000544507"/>
                <joint name="r_wrist_x_joint" pos="0 0 0" axis="1 0 0" range="-2.8798 2.8798" armature="0.00424198"/>
                <geom rgba="0.752941 0.752941 0.752941 1" mesh="r_wrist_x_link"/>
                <body name="r_wrist_y_link">
                  <inertial pos="-7.93971e-06 3.73154e-05 -0.00298556" quat="0.706031 -0.00238191 0.00374094 0.708167" mass="0.243805" diaginertia="0.000186763 0.00018369 0.000141736"/>
                  <joint name="r_wrist_y_joint" pos="0 0 0" axis="0 1 0" range="-1.309 1.309" armature="0.00424198"/>
                  <geom rgba="0.752941 0.752941 0.752941 1" mesh="r_wrist_y_link"/>
                  <body name="r_wrist_z_link">
                    <inertial pos="0.0308695 1.11972e-09 0.0141752" quat="0.924847 0 -0.380338 0" mass="0.106561" diaginertia="9.65613e-05 8.685e-05 4.53187e-05"/>
                    <joint name="r_wrist_z_joint" pos="0 0 0" axis="0 0 1" range="-0.7854 0.7854" armature="0.00424198"/>
                    <geom rgba="0.752941 0.752941 0.752941 1" mesh="r_wrist_z_link"/>
                    <geom name="r_wrist_z_collision" class="collision" size="0.03" pos="0.04 0 0" type="sphere" condim="1"/>
                  </body>
                </body>
              </body>
            </body>
          </body>
        </body>
      </body>
    </body>
  </worldbody>

  <!-- <actuator>
    <general name="waist_y_joint" joint="waist_y_joint" ctrllimited="false" forcelimited="true" forcerange="-90 90" biastype="affine" gainprm="108.448" biasprm="0 -108.448 -6.90402"/>
    <general name="waist_x_joint" joint="waist_x_joint" ctrllimited="false" forcelimited="true" forcerange="-100 100" biastype="affine" gainprm="162.672" biasprm="0 -162.672 -10.356"/>
    <general name="waist_z_joint" joint="waist_z_joint" ctrllimited="false" forcelimited="true" forcerange="-150 150" biastype="affine" gainprm="176.421" biasprm="0 -176.421 -11.2313"/>
    <general name="l_hip_y_joint" joint="l_hip_y_joint" ctrllimited="false" forcelimited="true" forcerange="-150 150" biastype="affine" gainprm="176.421" biasprm="0 -176.421 -11.2313"/>
    <general name="l_hip_x_joint" joint="l_hip_x_joint" ctrllimited="false" forcelimited="true" forcerange="-150 150" biastype="affine" gainprm="176.421" biasprm="0 -176.421 -11.2313"/>
    <general name="l_hip_z_joint" joint="l_hip_z_joint" ctrllimited="false" forcelimited="true" forcerange="-45 45" biastype="affine" gainprm="54.2241" biasprm="0 -54.2241 -3.45201"/>
    <general name="l_knee_y_joint" joint="l_knee_y_joint" ctrllimited="false" forcelimited="true" forcerange="-150 150" biastype="affine" gainprm="176.421" biasprm="0 -176.421 -11.2313"/>
    <general name="l_ankle_y_joint" joint="l_ankle_y_joint" ctrllimited="false" forcelimited="true" forcerange="-40 40" biastype="affine" gainprm="33.4934" biasprm="0 -33.4934 -2.13225"/>
    <general name="l_ankle_x_joint" joint="l_ankle_x_joint" ctrllimited="false" forcelimited="true" forcerange="-15 15" biastype="affine" gainprm="10" biasprm="0 -10 -1"/>
    <general name="r_hip_y_joint" joint="r_hip_y_joint" ctrllimited="false" forcelimited="true" forcerange="-150 150" biastype="affine" gainprm="176.421" biasprm="0 -176.421 -11.2313"/>
    <general name="r_hip_x_joint" joint="r_hip_x_joint" ctrllimited="false" forcelimited="true" forcerange="-150 150" biastype="affine" gainprm="176.421" biasprm="0 -176.421 -11.2313"/>
    <general name="r_hip_z_joint" joint="r_hip_z_joint" ctrllimited="false" forcelimited="true" forcerange="-45 45" biastype="affine" gainprm="54.2241" biasprm="0 -54.2241 -3.45201"/>
    <general name="r_knee_y_joint" joint="r_knee_y_joint" ctrllimited="false" forcelimited="true" forcerange="-150 150" biastype="affine" gainprm="176.421" biasprm="0 -176.421 -11.2313"/>
    <general name="r_ankle_y_joint" joint="r_ankle_y_joint" ctrllimited="false" forcelimited="true" forcerange="-40 40" biastype="affine" gainprm="33.4934" biasprm="0 -33.4934 -2.13225"/>
    <general name="r_ankle_x_joint" joint="r_ankle_x_joint" ctrllimited="false" forcelimited="true" forcerange="-15 15" biastype="affine" gainprm="10" biasprm="0 -10 -1"/>
    <general name="l_shoulder_y_joint" joint="l_shoulder_y_joint" ctrllimited="false" forcelimited="true" forcerange="-45 45" biastype="affine" gainprm="54.2241" biasprm="0 -54.2241 -3.45201"/>
    <general name="l_shoulder_x_joint" joint="l_shoulder_x_joint" ctrllimited="false" forcelimited="true" forcerange="-45 45" biastype="affine" gainprm="54.2241" biasprm="0 -54.2241 -3.45201"/>
    <general name="l_shoulder_z_joint" joint="l_shoulder_z_joint" ctrllimited="false" forcelimited="true" forcerange="-21 21" biastype="affine" gainprm="16.7467" biasprm="0 -16.7467 -1.06613"/>
    <general name="l_elbow_y_joint" joint="l_elbow_y_joint" ctrllimited="false" forcelimited="true" forcerange="-45 45" biastype="affine" gainprm="54.2241" biasprm="0 -54.2241 -3.45201"/>
    <general name="l_wrist_x_joint" joint="l_wrist_x_joint" ctrllimited="false" forcelimited="true" forcerange="-21 21" biastype="affine" gainprm="16.7467" biasprm="0 -16.7467 -1.06613"/>
    <general name="l_wrist_y_joint" joint="l_wrist_y_joint" ctrllimited="false" forcelimited="true" forcerange="-21 21" biastype="affine" gainprm="16.7467" biasprm="0 -16.7467 -1.06613"/>
    <general name="l_wrist_z_joint" joint="l_wrist_z_joint" ctrllimited="false" forcelimited="true" forcerange="-21 21" biastype="affine" gainprm="16.7467" biasprm="0 -16.7467 -1.06613"/>
    <general name="r_shoulder_y_joint" joint="r_shoulder_y_joint" ctrllimited="false" forcelimited="true" forcerange="-45 45" biastype="affine" gainprm="54.2241" biasprm="0 -54.2241 -3.45201"/>
    <general name="r_shoulder_x_joint" joint="r_shoulder_x_joint" ctrllimited="false" forcelimited="true" forcerange="-45 45" biastype="affine" gainprm="54.2241" biasprm="0 -54.2241 -3.45201"/>
    <general name="r_shoulder_z_joint" joint="r_shoulder_z_joint" ctrllimited="false" forcelimited="true" forcerange="-21 21" biastype="affine" gainprm="16.7467" biasprm="0 -16.7467 -1.06613"/>
    <general name="r_elbow_y_joint" joint="r_elbow_y_joint" ctrllimited="false" forcelimited="true" forcerange="-45 45" biastype="affine" gainprm="54.2241" biasprm="0 -54.2241 -3.45201"/>
    <general name="r_wrist_x_joint" joint="r_wrist_x_joint" ctrllimited="false" forcelimited="true" forcerange="-21 21" biastype="affine" gainprm="16.7467" biasprm="0 -16.7467 -1.06613"/>
    <general name="r_wrist_y_joint" joint="r_wrist_y_joint" ctrllimited="false" forcelimited="true" forcerange="-21 21" biastype="affine" gainprm="16.7467" biasprm="0 -16.7467 -1.06613"/>
    <general name="r_wrist_z_joint" joint="r_wrist_z_joint" ctrllimited="false" forcelimited="true" forcerange="-21 21" biastype="affine" gainprm="16.7467" biasprm="0 -16.7467 -1.06613"/>
  </actuator> -->

  <actuator>
    <motor name="waist_y_joint" joint="waist_y_joint" gear="1" ctrllimited='true' ctrlrange='-100 100'/>
    <motor name="waist_x_joint" joint="waist_x_joint" gear="1" ctrllimited='true' ctrlrange='-100 100'/>
    <motor name="waist_z_joint" joint="waist_z_joint" gear="1" ctrllimited='true' ctrlrange='-150 150'/>

    <motor name="l_hip_y_joint" joint="l_hip_y_joint" gear="1" ctrllimited='true' ctrlrange='-150 150'/>
    <motor name="l_hip_x_joint" joint="l_hip_x_joint" gear="1" ctrllimited='true' ctrlrange='-150 150'/>
    <motor name="l_hip_z_joint" joint="l_hip_z_joint" gear="1" ctrllimited='true' ctrlrange='-50 50'/>
    <motor name="l_knee_y_joint" joint="l_knee_y_joint" gear="1" ctrllimited='true' ctrlrange='-150 150'/>
    <motor name="l_ankle_y_joint" joint="l_ankle_y_joint" gear="1" ctrllimited='true' ctrlrange='-50 50'/>
    <motor name="l_ankle_x_joint" joint="l_ankle_x_joint" gear="1" ctrllimited='true' ctrlrange='-20 20'/>

    <motor name="r_hip_y_joint" joint="r_hip_y_joint" gear="1" ctrllimited='true' ctrlrange='-150 150'/>
    <motor name="r_hip_x_joint" joint="r_hip_x_joint" gear="1" ctrllimited='true' ctrlrange='-150 150'/>
    <motor name="r_hip_z_joint" joint="r_hip_z_joint" gear="1" ctrllimited='true' ctrlrange='-50 50'/>
    <motor name="r_knee_y_joint" joint="r_knee_y_joint" gear="1" ctrllimited='true' ctrlrange='-150 150'/>
    <motor name="r_ankle_y_joint" joint="r_ankle_y_joint" gear="1" ctrllimited='true' ctrlrange='-50 50'/>
    <motor name="r_ankle_x_joint" joint="r_ankle_x_joint" gear="1" ctrllimited='true' ctrlrange='-20 20'/>

    <motor name="l_shoulder_y_joint" joint="l_shoulder_y_joint" gear="1" ctrllimited='true' ctrlrange='-50 50'/>
    <motor name="l_shoulder_x_joint" joint="l_shoulder_x_joint" gear="1" ctrllimited='true' ctrlrange='-50 50'/>
    <motor name="l_shoulder_z_joint" joint="l_shoulder_z_joint" gear="1" ctrllimited='true' ctrlrange='-25 25'/>
    <motor name="l_elbow_y_joint" joint="l_elbow_y_joint" gear="1" ctrllimited='true' ctrlrange='-50 50'/>
    <motor name="l_wrist_x_joint" joint="l_wrist_x_joint" gear="1" ctrllimited='true' ctrlrange='-25 25'/>
    <motor name="l_wrist_y_joint" joint="l_wrist_y_joint" gear="1" ctrllimited='true' ctrlrange='-25 25'/>
    <motor name="l_wrist_z_joint" joint="l_wrist_z_joint" gear="1" ctrllimited='true' ctrlrange='-25 25'/>

    <motor name="r_shoulder_y_joint" joint="r_shoulder_y_joint" gear="1" ctrllimited='true' ctrlrange='-50 50'/>
    <motor name="r_shoulder_x_joint" joint="r_shoulder_x_joint" gear="1" ctrllimited='true' ctrlrange='-50 50'/>
    <motor name="r_shoulder_z_joint" joint="r_shoulder_z_joint" gear="1" ctrllimited='true' ctrlrange='-25 25'/>
    <motor name="r_elbow_y_joint" joint="r_elbow_y_joint" gear="1" ctrllimited='true' ctrlrange='-50 50'/>
    <motor name="r_wrist_x_joint" joint="r_wrist_x_joint" gear="1" ctrllimited='true' ctrlrange='-25 25'/>
    <motor name="r_wrist_y_joint" joint="r_wrist_y_joint" gear="1" ctrllimited='true' ctrlrange='-25 25'/>
    <motor name="r_wrist_z_joint" joint="r_wrist_z_joint" gear="1" ctrllimited='true' ctrlrange='-25 25'/>
  </actuator>

  <sensor>
    <gyro name="torso_ang_vel" site="imu_in_torso"/>
    <framequat name="torso_quat" objtype="site" objname="imu_in_torso"/>
    <velocimeter name="torso_lin_vel" site="imu_in_torso"/>
    <accelerometer name="torso_lin_acc" site="imu_in_torso"/>
  </sensor>

  <asset>
    <texture type="skybox" builtin="gradient" rgb1="0.3 0.5 0.7" rgb2="0 0 0" width="512" height="3072"/>
    <texture type="2d" name="groundplane" builtin="checker" mark="edge" rgb1="0.2 0.3 0.4" rgb2="0.1 0.2 0.3"
              markrgb="0.8 0.8 0.8" width="300" height="300"/>
    <material name="groundplane" texture="groundplane" texuniform="true" texrepeat="5 5" reflectance="0.2"/>
  </asset>

  <worldbody>
      <light pos="0 0 1.5" dir="0 0 -1" directional="true"/>
      <geom name="floor" size="0 0 0.01" type="plane" material="groundplane" />
  </worldbody>
</mujoco>
